*** Starting uWSGI 2.0.20 (64bit) on [Mon May 16 07:49:42 2022] ***
compiled with version: 10.2.1 20210110 on 16 May 2022 07:43:52
os: Linux-3.10.0-1160.62.1.el7.x86_64 #1 SMP Tue Apr 5 16:57:59 UTC 2022
nodename: 92d3dd22f80c
machine: x86_64
clock source: unix
pcre jit disabled
detected number of CPU cores: 2
current working directory: /var/www/html/Alzheimer_web
writing pidfile to /tmp/Alzheimer_web-master.pid
detected binary path: /usr/local/bin/uwsgi
chdir() to /var/www/html/Alzheimer_web
your memory page size is 4096 bytes
 *** WARNING: you have enabled harakiri without post buffering. Slow upload could be rejected on post-unbuffered webservers *** 
detected max file descriptor number: 1048576
lock engine: pthread robust mutexes
thunder lock: disabled (you can enable it with --thunder-lock)
uwsgi socket 0 bound to TCP address 0.0.0.0:8000 fd 3
setgid() to 33
setuid() to 33
Python version: 3.10.4 (main, May 11 2022, 07:15:55) [GCC 10.2.1 20210110]
*** Python threads support is disabled. You can enable it with --enable-threads ***
Python main interpreter initialized at 0x55d90dccdcc0
your server socket listen backlog is limited to 100 connections
your mercy for graceful operations on workers is 60 seconds
mapped 403077 bytes (393 KB) for 2 cores
*** Operational MODE: preforking ***
WSGI app 0 (mountpoint='') ready in 1 seconds on interpreter 0x55d90dccdcc0 pid: 11 (default app)
*** uWSGI is running in multiple interpreter mode ***
spawned uWSGI master process (pid: 11)
spawned uWSGI worker 1 (pid: 13, cores: 1)
spawned uWSGI worker 2 (pid: 14, cores: 1)
2022-05-16 15:49:52.587253: W tensorflow/stream_executor/platform/default/dso_loader.cc:64] Could not load dynamic library 'libcudart.so.11.0'; dlerror: libcudart.so.11.0: cannot open shared object file: No such file or directory
2022-05-16 15:49:52.587422: I tensorflow/stream_executor/cuda/cudart_stub.cc:29] Ignore above cudart dlerror if you do not have a GPU set up on your machine.
{address space usage: 1342312448 bytes/1280MB} {rss usage: 259469312 bytes/247MB} [pid: 14|app: 0|req: 1/1] 27.52.73.198 () {44 vars in 909 bytes} [Mon May 16 15:49:52 2022] GET /login/ => generated 3686 bytes in 2831 msecs (HTTP/1.1 200) 8 headers in 390 bytes (1 switches on core 0)
...The work of process 14 is done. Seeya!
worker 2 killed successfully (pid: 14)
Respawned uWSGI worker 2 (new pid: 16)
2022-05-16 15:50:16.732566: W tensorflow/stream_executor/platform/default/dso_loader.cc:64] Could not load dynamic library 'libcudart.so.11.0'; dlerror: libcudart.so.11.0: cannot open shared object file: No such file or directory
2022-05-16 15:50:16.732677: I tensorflow/stream_executor/cuda/cudart_stub.cc:29] Ignore above cudart dlerror if you do not have a GPU set up on your machine.
{address space usage: 1342357504 bytes/1280MB} {rss usage: 259440640 bytes/247MB} [pid: 16|app: 0|req: 2/2] 27.52.73.198 () {44 vars in 927 bytes} [Mon May 16 15:50:16 2022] GET /login/ => generated 3686 bytes in 2446 msecs (HTTP/1.1 200) 8 headers in 390 bytes (1 switches on core 0)
...The work of process 16 is done. Seeya!
worker 2 killed successfully (pid: 16)
Respawned uWSGI worker 2 (new pid: 18)
2022-05-16 15:50:21.404112: W tensorflow/stream_executor/platform/default/dso_loader.cc:64] Could not load dynamic library 'libcudart.so.11.0'; dlerror: libcudart.so.11.0: cannot open shared object file: No such file or directory
2022-05-16 15:50:21.404200: I tensorflow/stream_executor/cuda/cudart_stub.cc:29] Ignore above cudart dlerror if you do not have a GPU set up on your machine.
{address space usage: 1342349312 bytes/1280MB} {rss usage: 259276800 bytes/247MB} [pid: 13|app: 0|req: 1/3] 27.52.73.198 () {44 vars in 915 bytes} [Mon May 16 15:50:21 2022] GET / => generated 16548 bytes in 2276 msecs (HTTP/1.1 200) 7 headers in 223 bytes (1 switches on core 0)
...The work of process 13 is done. Seeya!
worker 1 killed successfully (pid: 13)
Respawned uWSGI worker 1 (new pid: 20)
2022-05-16 15:55:09.336187: W tensorflow/stream_executor/platform/default/dso_loader.cc:64] Could not load dynamic library 'libcudart.so.11.0'; dlerror: libcudart.so.11.0: cannot open shared object file: No such file or directory
2022-05-16 15:55:09.337053: I tensorflow/stream_executor/cuda/cudart_stub.cc:29] Ignore above cudart dlerror if you do not have a GPU set up on your machine.
{address space usage: 1342357504 bytes/1280MB} {rss usage: 259440640 bytes/247MB} [pid: 18|app: 0|req: 3/4] 27.52.73.198 () {44 vars in 921 bytes} [Mon May 16 15:55:08 2022] GET /login/ => generated 3686 bytes in 3224 msecs (HTTP/1.1 200) 8 headers in 390 bytes (1 switches on core 0)
...The work of process 18 is done. Seeya!
worker 2 killed successfully (pid: 18)
Respawned uWSGI worker 2 (new pid: 22)
2022-05-16 15:55:22.408985: W tensorflow/stream_executor/platform/default/dso_loader.cc:64] Could not load dynamic library 'libcudart.so.11.0'; dlerror: libcudart.so.11.0: cannot open shared object file: No such file or directory
2022-05-16 15:55:22.409076: I tensorflow/stream_executor/cuda/cudart_stub.cc:29] Ignore above cudart dlerror if you do not have a GPU set up on your machine.
{address space usage: 1342357504 bytes/1280MB} {rss usage: 259403776 bytes/247MB} [pid: 20|app: 0|req: 2/5] 27.52.73.198 () {44 vars in 986 bytes} [Mon May 16 15:55:21 2022] GET /accounts/google/login/?method=oauth2 => generated 636 bytes in 2396 msecs (HTTP/1.1 200) 8 headers in 389 bytes (1 switches on core 0)
...The work of process 20 is done. Seeya!
worker 1 killed successfully (pid: 20)
Respawned uWSGI worker 1 (new pid: 24)
2022-05-16 15:55:27.141351: W tensorflow/stream_executor/platform/default/dso_loader.cc:64] Could not load dynamic library 'libcudart.so.11.0'; dlerror: libcudart.so.11.0: cannot open shared object file: No such file or directory
2022-05-16 15:55:27.141470: I tensorflow/stream_executor/cuda/cudart_stub.cc:29] Ignore above cudart dlerror if you do not have a GPU set up on your machine.
{address space usage: 1342357504 bytes/1280MB} {rss usage: 259416064 bytes/247MB} [pid: 22|app: 0|req: 4/6] 27.52.73.198 () {44 vars in 959 bytes} [Mon May 16 15:55:26 2022] GET /accounts/github/login/ => generated 636 bytes in 2385 msecs (HTTP/1.1 200) 8 headers in 389 bytes (1 switches on core 0)
...The work of process 22 is done. Seeya!
worker 2 killed successfully (pid: 22)
Respawned uWSGI worker 2 (new pid: 26)
2022-05-16 15:55:30.938789: W tensorflow/stream_executor/platform/default/dso_loader.cc:64] Could not load dynamic library 'libcudart.so.11.0'; dlerror: libcudart.so.11.0: cannot open shared object file: No such file or directory
2022-05-16 15:55:30.938873: I tensorflow/stream_executor/cuda/cudart_stub.cc:29] Ignore above cudart dlerror if you do not have a GPU set up on your machine.
{address space usage: 1343406080 bytes/1281MB} {rss usage: 260435968 bytes/248MB} [pid: 24|app: 0|req: 3/7] 27.52.73.198 () {44 vars in 961 bytes} [Mon May 16 15:55:30 2022] GET /accounts/login/ => generated 1848 bytes in 2395 msecs (HTTP/1.1 200) 8 headers in 390 bytes (1 switches on core 0)
Internal Server Error: /accounts/github/login/
Traceback (most recent call last):
  File "/usr/local/lib/python3.10/site-packages/django/db/backends/utils.py", line 89, in _execute
    return self.cursor.execute(sql, params)
  File "/usr/local/lib/python3.10/site-packages/django/db/backends/sqlite3/base.py", line 477, in execute
    return Database.Cursor.execute(self, query, params)
sqlite3.OperationalError: attempt to write a readonly database

The above exception was the direct cause of the following exception:

Traceback (most recent call last):
  File "/usr/local/lib/python3.10/site-packages/django/core/handlers/exception.py", line 55, in inner
    response = get_response(request)
  File "/usr/local/lib/python3.10/site-packages/django/utils/deprecation.py", line 136, in __call__
    response = self.process_response(request, response)
  File "/usr/local/lib/python3.10/site-packages/django/contrib/sessions/middleware.py", line 59, in process_response
    request.session.save()
  File "/usr/local/lib/python3.10/site-packages/django/contrib/sessions/backends/db.py", line 80, in save
    return self.create()
  File "/usr/local/lib/python3.10/site-packages/django/contrib/sessions/backends/db.py", line 54, in create
    self.save(must_create=True)
  File "/usr/local/lib/python3.10/site-packages/django/contrib/sessions/backends/db.py", line 86, in save
    obj.save(
  File "/usr/local/lib/python3.10/site-packages/django/db/models/base.py", line 806, in save
    self.save_base(
  File "/usr/local/lib/python3.10/site-packages/django/db/models/base.py", line 857, in save_base
    updated = self._save_table(
  File "/usr/local/lib/python3.10/site-packages/django/db/models/base.py", line 1000, in _save_table
    results = self._do_insert(
  File "/usr/local/lib/python3.10/site-packages/django/db/models/base.py", line 1041, in _do_insert
    return manager._insert(
  File "/usr/local/lib/python3.10/site-packages/django/db/models/manager.py", line 85, in manager_method
    return getattr(self.get_queryset(), name)(*args, **kwargs)
  File "/usr/local/lib/python3.10/site-packages/django/db/models/query.py", line 1434, in _insert
    return query.get_compiler(using=using).execute_sql(returning_fields)
  File "/usr/local/lib/python3.10/site-packages/django/db/models/sql/compiler.py", line 1621, in execute_sql
    cursor.execute(sql, params)
  File "/usr/local/lib/python3.10/site-packages/django/db/backends/utils.py", line 103, in execute
    return super().execute(sql, params)
  File "/usr/local/lib/python3.10/site-packages/django/db/backends/utils.py", line 67, in execute
    return self._execute_with_wrappers(
  File "/usr/local/lib/python3.10/site-packages/django/db/backends/utils.py", line 80, in _execute_with_wrappers
    return executor(sql, params, many, context)
  File "/usr/local/lib/python3.10/site-packages/django/db/backends/utils.py", line 84, in _execute
    with self.db.wrap_database_errors:
  File "/usr/local/lib/python3.10/site-packages/django/db/utils.py", line 91, in __exit__
    raise dj_exc_value.with_traceback(traceback) from exc_value
  File "/usr/local/lib/python3.10/site-packages/django/db/backends/utils.py", line 89, in _execute
    return self.cursor.execute(sql, params)
  File "/usr/local/lib/python3.10/site-packages/django/db/backends/sqlite3/base.py", line 477, in execute
    return Database.Cursor.execute(self, query, params)
django.db.utils.OperationalError: attempt to write a readonly database
{address space usage: 1344651264 bytes/1282MB} {rss usage: 262111232 bytes/249MB} [pid: 24|app: 0|req: 4/8] 27.52.73.198 () {52 vars in 1162 bytes} [Mon May 16 15:55:36 2022] POST /accounts/github/login/ => generated 148168 bytes in 98 msecs (HTTP/1.1 500) 4 headers in 167 bytes (1 switches on core 0)
...The work of process 24 is done. Seeya!
worker 1 killed successfully (pid: 24)
Respawned uWSGI worker 1 (new pid: 28)
2022-05-16 15:55:51.552913: W tensorflow/stream_executor/platform/default/dso_loader.cc:64] Could not load dynamic library 'libcudart.so.11.0'; dlerror: libcudart.so.11.0: cannot open shared object file: No such file or directory
2022-05-16 15:55:51.553007: I tensorflow/stream_executor/cuda/cudart_stub.cc:29] Ignore above cudart dlerror if you do not have a GPU set up on your machine.
{address space usage: 1342357504 bytes/1280MB} {rss usage: 259440640 bytes/247MB} [pid: 26|app: 0|req: 5/9] 27.52.73.198 () {44 vars in 927 bytes} [Mon May 16 15:55:51 2022] GET /login/ => generated 3686 bytes in 2295 msecs (HTTP/1.1 200) 8 headers in 390 bytes (1 switches on core 0)
...The work of process 26 is done. Seeya!
worker 2 killed successfully (pid: 26)
Respawned uWSGI worker 2 (new pid: 30)
2022-05-16 15:56:00.496031: W tensorflow/stream_executor/platform/default/dso_loader.cc:64] Could not load dynamic library 'libcudart.so.11.0'; dlerror: libcudart.so.11.0: cannot open shared object file: No such file or directory
2022-05-16 15:56:00.496407: I tensorflow/stream_executor/cuda/cudart_stub.cc:29] Ignore above cudart dlerror if you do not have a GPU set up on your machine.
{address space usage: 1342357504 bytes/1280MB} {rss usage: 259440640 bytes/247MB} [pid: 28|app: 0|req: 5/10] 27.52.73.198 () {44 vars in 927 bytes} [Mon May 16 15:55:59 2022] GET /login/ => generated 3686 bytes in 4234 msecs (HTTP/1.1 200) 8 headers in 390 bytes (1 switches on core 0)
...The work of process 28 is done. Seeya!
worker 1 killed successfully (pid: 28)
Respawned uWSGI worker 1 (new pid: 32)
2022-05-16 15:56:06.690211: W tensorflow/stream_executor/platform/default/dso_loader.cc:64] Could not load dynamic library 'libcudart.so.11.0'; dlerror: libcudart.so.11.0: cannot open shared object file: No such file or directory
2022-05-16 15:56:06.690327: I tensorflow/stream_executor/cuda/cudart_stub.cc:29] Ignore above cudart dlerror if you do not have a GPU set up on your machine.
{address space usage: 1342357504 bytes/1280MB} {rss usage: 259584000 bytes/247MB} [pid: 30|app: 0|req: 6/11] 27.52.73.198 () {44 vars in 933 bytes} [Mon May 16 15:56:06 2022] GET /register/ => generated 4155 bytes in 2474 msecs (HTTP/1.1 200) 8 headers in 390 bytes (1 switches on core 0)
...The work of process 30 is done. Seeya!
worker 2 killed successfully (pid: 30)
Respawned uWSGI worker 2 (new pid: 34)
2022-05-16 15:56:21.135249: W tensorflow/stream_executor/platform/default/dso_loader.cc:64] Could not load dynamic library 'libcudart.so.11.0'; dlerror: libcudart.so.11.0: cannot open shared object file: No such file or directory
2022-05-16 15:56:21.135381: I tensorflow/stream_executor/cuda/cudart_stub.cc:29] Ignore above cudart dlerror if you do not have a GPU set up on your machine.
{address space usage: 1346555904 bytes/1284MB} {rss usage: 264056832 bytes/251MB} [pid: 32|app: 0|req: 6/12] 27.52.73.198 () {52 vars in 1125 bytes} [Mon May 16 15:56:20 2022] POST /register/ => generated 4484 bytes in 2378 msecs (HTTP/1.1 200) 8 headers in 390 bytes (1 switches on core 0)
...The work of process 32 is done. Seeya!
worker 1 killed successfully (pid: 32)
Respawned uWSGI worker 1 (new pid: 36)
2022-05-16 15:56:36.120241: W tensorflow/stream_executor/platform/default/dso_loader.cc:64] Could not load dynamic library 'libcudart.so.11.0'; dlerror: libcudart.so.11.0: cannot open shared object file: No such file or directory
2022-05-16 15:56:36.120374: I tensorflow/stream_executor/cuda/cudart_stub.cc:29] Ignore above cudart dlerror if you do not have a GPU set up on your machine.
{address space usage: 1346555904 bytes/1284MB} {rss usage: 263888896 bytes/251MB} [pid: 34|app: 0|req: 7/13] 27.52.73.198 () {52 vars in 1125 bytes} [Mon May 16 15:56:35 2022] POST /register/ => generated 4385 bytes in 2383 msecs (HTTP/1.1 200) 8 headers in 390 bytes (1 switches on core 0)
...The work of process 34 is done. Seeya!
worker 2 killed successfully (pid: 34)
Respawned uWSGI worker 2 (new pid: 38)
2022-05-16 15:56:50.384891: W tensorflow/stream_executor/platform/default/dso_loader.cc:64] Could not load dynamic library 'libcudart.so.11.0'; dlerror: libcudart.so.11.0: cannot open shared object file: No such file or directory
2022-05-16 15:56:50.384984: I tensorflow/stream_executor/cuda/cudart_stub.cc:29] Ignore above cudart dlerror if you do not have a GPU set up on your machine.
{address space usage: 1346555904 bytes/1284MB} {rss usage: 263888896 bytes/251MB} [pid: 36|app: 0|req: 7/14] 27.52.73.198 () {52 vars in 1125 bytes} [Mon May 16 15:56:49 2022] POST /register/ => generated 4385 bytes in 2397 msecs (HTTP/1.1 200) 8 headers in 390 bytes (1 switches on core 0)
...The work of process 36 is done. Seeya!
worker 1 killed successfully (pid: 36)
Respawned uWSGI worker 1 (new pid: 40)
2022-05-16 15:57:56.298851: W tensorflow/stream_executor/platform/default/dso_loader.cc:64] Could not load dynamic library 'libcudart.so.11.0'; dlerror: libcudart.so.11.0: cannot open shared object file: No such file or directory
2022-05-16 15:57:56.298944: I tensorflow/stream_executor/cuda/cudart_stub.cc:29] Ignore above cudart dlerror if you do not have a GPU set up on your machine.
Internal Server Error: /register/
Traceback (most recent call last):
  File "/usr/local/lib/python3.10/site-packages/django/db/backends/utils.py", line 89, in _execute
    return self.cursor.execute(sql, params)
  File "/usr/local/lib/python3.10/site-packages/django/db/backends/sqlite3/base.py", line 477, in execute
    return Database.Cursor.execute(self, query, params)
sqlite3.OperationalError: attempt to write a readonly database

The above exception was the direct cause of the following exception:

Traceback (most recent call last):
  File "/usr/local/lib/python3.10/site-packages/django/core/handlers/exception.py", line 55, in inner
    response = get_response(request)
  File "/usr/local/lib/python3.10/site-packages/django/core/handlers/base.py", line 197, in _get_response
    response = wrapped_callback(request, *callback_args, **callback_kwargs)
  File "/var/www/html/Alzheimer_web/./login/views.py", line 15, in sign_up
    form.save()
  File "/usr/local/lib/python3.10/site-packages/django/contrib/auth/forms.py", line 143, in save
    user.save()
  File "/usr/local/lib/python3.10/site-packages/django/contrib/auth/base_user.py", line 68, in save
    super().save(*args, **kwargs)
  File "/usr/local/lib/python3.10/site-packages/django/db/models/base.py", line 806, in save
    self.save_base(
  File "/usr/local/lib/python3.10/site-packages/django/db/models/base.py", line 857, in save_base
    updated = self._save_table(
  File "/usr/local/lib/python3.10/site-packages/django/db/models/base.py", line 1000, in _save_table
    results = self._do_insert(
  File "/usr/local/lib/python3.10/site-packages/django/db/models/base.py", line 1041, in _do_insert
    return manager._insert(
  File "/usr/local/lib/python3.10/site-packages/django/db/models/manager.py", line 85, in manager_method
    return getattr(self.get_queryset(), name)(*args, **kwargs)
  File "/usr/local/lib/python3.10/site-packages/django/db/models/query.py", line 1434, in _insert
    return query.get_compiler(using=using).execute_sql(returning_fields)
  File "/usr/local/lib/python3.10/site-packages/django/db/models/sql/compiler.py", line 1621, in execute_sql
    cursor.execute(sql, params)
  File "/usr/local/lib/python3.10/site-packages/django/db/backends/utils.py", line 103, in execute
    return super().execute(sql, params)
  File "/usr/local/lib/python3.10/site-packages/django/db/backends/utils.py", line 67, in execute
    return self._execute_with_wrappers(
  File "/usr/local/lib/python3.10/site-packages/django/db/backends/utils.py", line 80, in _execute_with_wrappers
    return executor(sql, params, many, context)
  File "/usr/local/lib/python3.10/site-packages/django/db/backends/utils.py", line 84, in _execute
    with self.db.wrap_database_errors:
  File "/usr/local/lib/python3.10/site-packages/django/db/utils.py", line 91, in __exit__
    raise dj_exc_value.with_traceback(traceback) from exc_value
  File "/usr/local/lib/python3.10/site-packages/django/db/backends/utils.py", line 89, in _execute
    return self.cursor.execute(sql, params)
  File "/usr/local/lib/python3.10/site-packages/django/db/backends/sqlite3/base.py", line 477, in execute
    return Database.Cursor.execute(self, query, params)
django.db.utils.OperationalError: attempt to write a readonly database
{address space usage: 1347604480 bytes/1285MB} {rss usage: 264802304 bytes/252MB} [pid: 40|app: 0|req: 8/15] 27.52.73.198 () {52 vars in 1125 bytes} [Mon May 16 15:57:55 2022] POST /register/ => generated 147265 bytes in 2621 msecs (HTTP/1.1 500) 7 headers in 228 bytes (1 switches on core 0)
...The work of process 40 is done. Seeya!
worker 1 killed successfully (pid: 40)
Respawned uWSGI worker 1 (new pid: 42)
*** Starting uWSGI 2.0.20 (64bit) on [Mon May 16 08:01:18 2022] ***
compiled with version: 10.2.1 20210110 on 16 May 2022 07:43:52
os: Linux-3.10.0-1160.62.1.el7.x86_64 #1 SMP Tue Apr 5 16:57:59 UTC 2022
nodename: 92d3dd22f80c
machine: x86_64
clock source: unix
pcre jit disabled
detected number of CPU cores: 2
current working directory: /var/www/html/Alzheimer_web
writing pidfile to /tmp/Alzheimer_web-master.pid
detected binary path: /usr/local/bin/uwsgi
chdir() to /var/www/html/Alzheimer_web
your memory page size is 4096 bytes
 *** WARNING: you have enabled harakiri without post buffering. Slow upload could be rejected on post-unbuffered webservers *** 
detected max file descriptor number: 1048576
lock engine: pthread robust mutexes
thunder lock: disabled (you can enable it with --thunder-lock)
uwsgi socket 0 bound to TCP address 0.0.0.0:8000 fd 3
setgid() to 33
setuid() to 33
Python version: 3.10.4 (main, May 11 2022, 07:15:55) [GCC 10.2.1 20210110]
*** Python threads support is disabled. You can enable it with --enable-threads ***
Python main interpreter initialized at 0x55e6d33afcc0
your server socket listen backlog is limited to 100 connections
your mercy for graceful operations on workers is 60 seconds
mapped 403077 bytes (393 KB) for 2 cores
*** Operational MODE: preforking ***
WSGI app 0 (mountpoint='') ready in 1 seconds on interpreter 0x55e6d33afcc0 pid: 11 (default app)
*** uWSGI is running in multiple interpreter mode ***
spawned uWSGI master process (pid: 11)
spawned uWSGI worker 1 (pid: 13, cores: 1)
spawned uWSGI worker 2 (pid: 14, cores: 1)
*** Starting uWSGI 2.0.20 (64bit) on [Mon May 16 08:01:53 2022] ***
compiled with version: 10.2.1 20210110 on 16 May 2022 07:43:52
os: Linux-3.10.0-1160.62.1.el7.x86_64 #1 SMP Tue Apr 5 16:57:59 UTC 2022
nodename: 92d3dd22f80c
machine: x86_64
clock source: unix
pcre jit disabled
detected number of CPU cores: 2
current working directory: /var/www/html/Alzheimer_web
writing pidfile to /tmp/Alzheimer_web-master.pid
detected binary path: /usr/local/bin/uwsgi
chdir() to /var/www/html/Alzheimer_web
your memory page size is 4096 bytes
 *** WARNING: you have enabled harakiri without post buffering. Slow upload could be rejected on post-unbuffered webservers *** 
detected max file descriptor number: 1048576
lock engine: pthread robust mutexes
thunder lock: disabled (you can enable it with --thunder-lock)
uwsgi socket 0 bound to TCP address 0.0.0.0:8000 fd 3
setgid() to 33
setuid() to 33
Python version: 3.10.4 (main, May 11 2022, 07:15:55) [GCC 10.2.1 20210110]
*** Python threads support is disabled. You can enable it with --enable-threads ***
Python main interpreter initialized at 0x55adecacecc0
your server socket listen backlog is limited to 100 connections
your mercy for graceful operations on workers is 60 seconds
mapped 403077 bytes (393 KB) for 2 cores
*** Operational MODE: preforking ***
WSGI app 0 (mountpoint='') ready in 1 seconds on interpreter 0x55adecacecc0 pid: 11 (default app)
*** uWSGI is running in multiple interpreter mode ***
spawned uWSGI master process (pid: 11)
spawned uWSGI worker 1 (pid: 13, cores: 1)
spawned uWSGI worker 2 (pid: 14, cores: 1)
*** Starting uWSGI 2.0.20 (64bit) on [Mon May 16 08:12:30 2022] ***
compiled with version: 10.2.1 20210110 on 16 May 2022 07:43:52
os: Linux-3.10.0-1160.62.1.el7.x86_64 #1 SMP Tue Apr 5 16:57:59 UTC 2022
nodename: 92d3dd22f80c
machine: x86_64
clock source: unix
pcre jit disabled
detected number of CPU cores: 2
current working directory: /var/www/html/Alzheimer_web
writing pidfile to /tmp/Alzheimer_web-master.pid
detected binary path: /usr/local/bin/uwsgi
chdir() to /var/www/html/Alzheimer_web
your memory page size is 4096 bytes
 *** WARNING: you have enabled harakiri without post buffering. Slow upload could be rejected on post-unbuffered webservers *** 
detected max file descriptor number: 1048576
lock engine: pthread robust mutexes
thunder lock: disabled (you can enable it with --thunder-lock)
uwsgi socket 0 bound to TCP address 0.0.0.0:8000 fd 3
setgid() to 33
setuid() to 33
Python version: 3.10.4 (main, May 11 2022, 07:15:55) [GCC 10.2.1 20210110]
*** Python threads support is disabled. You can enable it with --enable-threads ***
Python main interpreter initialized at 0x558851085dd0
your server socket listen backlog is limited to 100 connections
your mercy for graceful operations on workers is 60 seconds
mapped 403077 bytes (393 KB) for 2 cores
*** Operational MODE: preforking ***
WSGI app 0 (mountpoint='') ready in 1 seconds on interpreter 0x558851085dd0 pid: 11 (default app)
*** uWSGI is running in multiple interpreter mode ***
spawned uWSGI master process (pid: 11)
spawned uWSGI worker 1 (pid: 13, cores: 1)
spawned uWSGI worker 2 (pid: 14, cores: 1)
2022-05-16 16:12:48.046102: W tensorflow/stream_executor/platform/default/dso_loader.cc:64] Could not load dynamic library 'libcudart.so.11.0'; dlerror: libcudart.so.11.0: cannot open shared object file: No such file or directory
2022-05-16 16:12:48.046194: I tensorflow/stream_executor/cuda/cudart_stub.cc:29] Ignore above cudart dlerror if you do not have a GPU set up on your machine.
{address space usage: 1342349312 bytes/1280MB} {rss usage: 260984832 bytes/248MB} [pid: 14|app: 0|req: 1/1] 27.52.73.198 () {44 vars in 918 bytes} [Mon May 16 16:12:47 2022] GET / => generated 16548 bytes in 2618 msecs (HTTP/1.1 200) 7 headers in 223 bytes (1 switches on core 0)
...The work of process 14 is done. Seeya!
worker 2 killed successfully (pid: 14)
Respawned uWSGI worker 2 (new pid: 16)
2022-05-16 16:13:16.094762: W tensorflow/stream_executor/platform/default/dso_loader.cc:64] Could not load dynamic library 'libcudart.so.11.0'; dlerror: libcudart.so.11.0: cannot open shared object file: No such file or directory
2022-05-16 16:13:16.094885: I tensorflow/stream_executor/cuda/cudart_stub.cc:29] Ignore above cudart dlerror if you do not have a GPU set up on your machine.
{address space usage: 1342357504 bytes/1280MB} {rss usage: 260939776 bytes/248MB} [pid: 13|app: 0|req: 1/2] 27.52.73.198 () {44 vars in 921 bytes} [Mon May 16 16:13:15 2022] GET /login/ => generated 3686 bytes in 2486 msecs (HTTP/1.1 200) 8 headers in 390 bytes (1 switches on core 0)
...The work of process 13 is done. Seeya!
worker 1 killed successfully (pid: 13)
Respawned uWSGI worker 1 (new pid: 18)
2022-05-16 16:16:09.663764: W tensorflow/stream_executor/platform/default/dso_loader.cc:64] Could not load dynamic library 'libcudart.so.11.0'; dlerror: libcudart.so.11.0: cannot open shared object file: No such file or directory
2022-05-16 16:16:09.663897: I tensorflow/stream_executor/cuda/cudart_stub.cc:29] Ignore above cudart dlerror if you do not have a GPU set up on your machine.
{address space usage: 1342349312 bytes/1280MB} {rss usage: 260972544 bytes/248MB} [pid: 16|app: 0|req: 2/3] 193.124.7.9 () {32 vars in 358 bytes} [Mon May 16 16:16:09 2022] GET / => generated 16548 bytes in 2371 msecs (HTTP/1.1 200) 7 headers in 223 bytes (1 switches on core 0)
...The work of process 16 is done. Seeya!
worker 2 killed successfully (pid: 16)
Respawned uWSGI worker 2 (new pid: 31)
2022-05-16 16:16:17.393556: W tensorflow/stream_executor/platform/default/dso_loader.cc:64] Could not load dynamic library 'libcudart.so.11.0'; dlerror: libcudart.so.11.0: cannot open shared object file: No such file or directory
2022-05-16 16:16:17.393662: I tensorflow/stream_executor/cuda/cudart_stub.cc:29] Ignore above cudart dlerror if you do not have a GPU set up on your machine.
{address space usage: 1342353408 bytes/1280MB} {rss usage: 260943872 bytes/248MB} [pid: 18|app: 0|req: 2/4] 27.52.73.198 () {44 vars in 927 bytes} [Mon May 16 16:16:16 2022] GET /login/ => generated 3686 bytes in 2414 msecs (HTTP/1.1 200) 8 headers in 390 bytes (1 switches on core 0)
...The work of process 18 is done. Seeya!
worker 1 killed successfully (pid: 18)
Respawned uWSGI worker 1 (new pid: 33)
2022-05-16 16:16:24.609156: W tensorflow/stream_executor/platform/default/dso_loader.cc:64] Could not load dynamic library 'libcudart.so.11.0'; dlerror: libcudart.so.11.0: cannot open shared object file: No such file or directory
2022-05-16 16:16:24.609260: I tensorflow/stream_executor/cuda/cudart_stub.cc:29] Ignore above cudart dlerror if you do not have a GPU set up on your machine.
{address space usage: 1342353408 bytes/1280MB} {rss usage: 260939776 bytes/248MB} [pid: 31|app: 0|req: 3/5] 27.52.73.198 () {44 vars in 959 bytes} [Mon May 16 16:16:24 2022] GET /accounts/github/login/ => generated 636 bytes in 2724 msecs (HTTP/1.1 200) 8 headers in 389 bytes (1 switches on core 0)
...The work of process 31 is done. Seeya!
worker 2 killed successfully (pid: 31)
Respawned uWSGI worker 2 (new pid: 35)
2022-05-16 16:16:29.668729: W tensorflow/stream_executor/platform/default/dso_loader.cc:64] Could not load dynamic library 'libcudart.so.11.0'; dlerror: libcudart.so.11.0: cannot open shared object file: No such file or directory
2022-05-16 16:16:29.668829: I tensorflow/stream_executor/cuda/cudart_stub.cc:29] Ignore above cudart dlerror if you do not have a GPU set up on your machine.
{address space usage: 1343401984 bytes/1281MB} {rss usage: 261939200 bytes/249MB} [pid: 33|app: 0|req: 3/6] 27.52.73.198 () {44 vars in 963 bytes} [Mon May 16 16:16:29 2022] GET /accounts/signup/ => generated 1532 bytes in 2337 msecs (HTTP/1.1 200) 8 headers in 390 bytes (1 switches on core 0)
...The work of process 33 is done. Seeya!
worker 1 killed successfully (pid: 33)
Respawned uWSGI worker 1 (new pid: 37)
2022-05-16 16:16:36.495732: W tensorflow/stream_executor/platform/default/dso_loader.cc:64] Could not load dynamic library 'libcudart.so.11.0'; dlerror: libcudart.so.11.0: cannot open shared object file: No such file or directory
2022-05-16 16:16:36.495822: I tensorflow/stream_executor/cuda/cudart_stub.cc:29] Ignore above cudart dlerror if you do not have a GPU set up on your machine.
Internal Server Error: /accounts/github/login/
Traceback (most recent call last):
  File "/usr/local/lib/python3.10/site-packages/django/db/backends/utils.py", line 89, in _execute
    return self.cursor.execute(sql, params)
  File "/usr/local/lib/python3.10/site-packages/django/db/backends/sqlite3/base.py", line 477, in execute
    return Database.Cursor.execute(self, query, params)
sqlite3.OperationalError: attempt to write a readonly database

The above exception was the direct cause of the following exception:

Traceback (most recent call last):
  File "/usr/local/lib/python3.10/site-packages/django/core/handlers/exception.py", line 55, in inner
    response = get_response(request)
  File "/usr/local/lib/python3.10/site-packages/django/utils/deprecation.py", line 136, in __call__
    response = self.process_response(request, response)
  File "/usr/local/lib/python3.10/site-packages/django/contrib/sessions/middleware.py", line 59, in process_response
    request.session.save()
  File "/usr/local/lib/python3.10/site-packages/django/contrib/sessions/backends/db.py", line 80, in save
    return self.create()
  File "/usr/local/lib/python3.10/site-packages/django/contrib/sessions/backends/db.py", line 54, in create
    self.save(must_create=True)
  File "/usr/local/lib/python3.10/site-packages/django/contrib/sessions/backends/db.py", line 86, in save
    obj.save(
  File "/usr/local/lib/python3.10/site-packages/django/db/models/base.py", line 806, in save
    self.save_base(
  File "/usr/local/lib/python3.10/site-packages/django/db/models/base.py", line 857, in save_base
    updated = self._save_table(
  File "/usr/local/lib/python3.10/site-packages/django/db/models/base.py", line 1000, in _save_table
    results = self._do_insert(
  File "/usr/local/lib/python3.10/site-packages/django/db/models/base.py", line 1041, in _do_insert
    return manager._insert(
  File "/usr/local/lib/python3.10/site-packages/django/db/models/manager.py", line 85, in manager_method
    return getattr(self.get_queryset(), name)(*args, **kwargs)
  File "/usr/local/lib/python3.10/site-packages/django/db/models/query.py", line 1434, in _insert
    return query.get_compiler(using=using).execute_sql(returning_fields)
  File "/usr/local/lib/python3.10/site-packages/django/db/models/sql/compiler.py", line 1621, in execute_sql
    cursor.execute(sql, params)
  File "/usr/local/lib/python3.10/site-packages/django/db/backends/utils.py", line 103, in execute
    return super().execute(sql, params)
  File "/usr/local/lib/python3.10/site-packages/django/db/backends/utils.py", line 67, in execute
    return self._execute_with_wrappers(
  File "/usr/local/lib/python3.10/site-packages/django/db/backends/utils.py", line 80, in _execute_with_wrappers
    return executor(sql, params, many, context)
  File "/usr/local/lib/python3.10/site-packages/django/db/backends/utils.py", line 84, in _execute
    with self.db.wrap_database_errors:
  File "/usr/local/lib/python3.10/site-packages/django/db/utils.py", line 91, in __exit__
    raise dj_exc_value.with_traceback(traceback) from exc_value
  File "/usr/local/lib/python3.10/site-packages/django/db/backends/utils.py", line 89, in _execute
    return self.cursor.execute(sql, params)
  File "/usr/local/lib/python3.10/site-packages/django/db/backends/sqlite3/base.py", line 477, in execute
    return Database.Cursor.execute(self, query, params)
django.db.utils.OperationalError: attempt to write a readonly database
{address space usage: 1344442368 bytes/1282MB} {rss usage: 263335936 bytes/251MB} [pid: 35|app: 0|req: 4/7] 27.52.73.198 () {52 vars in 1162 bytes} [Mon May 16 16:16:36 2022] POST /accounts/github/login/ => generated 148169 bytes in 2380 msecs (HTTP/1.1 500) 4 headers in 167 bytes (2 switches on core 0)
...The work of process 35 is done. Seeya!
worker 2 killed successfully (pid: 35)
Respawned uWSGI worker 2 (new pid: 39)
2022-05-16 16:16:42.506367: W tensorflow/stream_executor/platform/default/dso_loader.cc:64] Could not load dynamic library 'libcudart.so.11.0'; dlerror: libcudart.so.11.0: cannot open shared object file: No such file or directory
2022-05-16 16:16:42.506464: I tensorflow/stream_executor/cuda/cudart_stub.cc:29] Ignore above cudart dlerror if you do not have a GPU set up on your machine.
{address space usage: 1342353408 bytes/1280MB} {rss usage: 261083136 bytes/248MB} [pid: 37|app: 0|req: 4/8] 27.52.73.198 () {44 vars in 933 bytes} [Mon May 16 16:16:42 2022] GET /register/ => generated 4155 bytes in 2343 msecs (HTTP/1.1 200) 8 headers in 390 bytes (1 switches on core 0)
...The work of process 37 is done. Seeya!
worker 1 killed successfully (pid: 37)
Respawned uWSGI worker 1 (new pid: 41)
2022-05-16 16:16:51.838841: W tensorflow/stream_executor/platform/default/dso_loader.cc:64] Could not load dynamic library 'libcudart.so.11.0'; dlerror: libcudart.so.11.0: cannot open shared object file: No such file or directory
2022-05-16 16:16:51.838930: I tensorflow/stream_executor/cuda/cudart_stub.cc:29] Ignore above cudart dlerror if you do not have a GPU set up on your machine.
{address space usage: 1342353408 bytes/1280MB} {rss usage: 260939776 bytes/248MB} [pid: 39|app: 0|req: 5/9] 27.52.73.198 () {44 vars in 959 bytes} [Mon May 16 16:16:51 2022] GET /accounts/github/login/ => generated 636 bytes in 2275 msecs (HTTP/1.1 200) 8 headers in 389 bytes (1 switches on core 0)
...The work of process 39 is done. Seeya!
worker 2 killed successfully (pid: 39)
Respawned uWSGI worker 2 (new pid: 43)
2022-05-16 16:16:57.874526: W tensorflow/stream_executor/platform/default/dso_loader.cc:64] Could not load dynamic library 'libcudart.so.11.0'; dlerror: libcudart.so.11.0: cannot open shared object file: No such file or directory
2022-05-16 16:16:57.874627: I tensorflow/stream_executor/cuda/cudart_stub.cc:29] Ignore above cudart dlerror if you do not have a GPU set up on your machine.
Internal Server Error: /accounts/github/login/
Traceback (most recent call last):
  File "/usr/local/lib/python3.10/site-packages/django/db/backends/utils.py", line 89, in _execute
    return self.cursor.execute(sql, params)
  File "/usr/local/lib/python3.10/site-packages/django/db/backends/sqlite3/base.py", line 477, in execute
    return Database.Cursor.execute(self, query, params)
sqlite3.OperationalError: attempt to write a readonly database

The above exception was the direct cause of the following exception:

Traceback (most recent call last):
  File "/usr/local/lib/python3.10/site-packages/django/core/handlers/exception.py", line 55, in inner
    response = get_response(request)
  File "/usr/local/lib/python3.10/site-packages/django/utils/deprecation.py", line 136, in __call__
    response = self.process_response(request, response)
  File "/usr/local/lib/python3.10/site-packages/django/contrib/sessions/middleware.py", line 59, in process_response
    request.session.save()
  File "/usr/local/lib/python3.10/site-packages/django/contrib/sessions/backends/db.py", line 80, in save
    return self.create()
  File "/usr/local/lib/python3.10/site-packages/django/contrib/sessions/backends/db.py", line 54, in create
    self.save(must_create=True)
  File "/usr/local/lib/python3.10/site-packages/django/contrib/sessions/backends/db.py", line 86, in save
    obj.save(
  File "/usr/local/lib/python3.10/site-packages/django/db/models/base.py", line 806, in save
    self.save_base(
  File "/usr/local/lib/python3.10/site-packages/django/db/models/base.py", line 857, in save_base
    updated = self._save_table(
  File "/usr/local/lib/python3.10/site-packages/django/db/models/base.py", line 1000, in _save_table
    results = self._do_insert(
  File "/usr/local/lib/python3.10/site-packages/django/db/models/base.py", line 1041, in _do_insert
    return manager._insert(
  File "/usr/local/lib/python3.10/site-packages/django/db/models/manager.py", line 85, in manager_method
    return getattr(self.get_queryset(), name)(*args, **kwargs)
  File "/usr/local/lib/python3.10/site-packages/django/db/models/query.py", line 1434, in _insert
    return query.get_compiler(using=using).execute_sql(returning_fields)
  File "/usr/local/lib/python3.10/site-packages/django/db/models/sql/compiler.py", line 1621, in execute_sql
    cursor.execute(sql, params)
  File "/usr/local/lib/python3.10/site-packages/django/db/backends/utils.py", line 103, in execute
    return super().execute(sql, params)
  File "/usr/local/lib/python3.10/site-packages/django/db/backends/utils.py", line 67, in execute
    return self._execute_with_wrappers(
  File "/usr/local/lib/python3.10/site-packages/django/db/backends/utils.py", line 80, in _execute_with_wrappers
    return executor(sql, params, many, context)
  File "/usr/local/lib/python3.10/site-packages/django/db/backends/utils.py", line 84, in _execute
    with self.db.wrap_database_errors:
  File "/usr/local/lib/python3.10/site-packages/django/db/utils.py", line 91, in __exit__
    raise dj_exc_value.with_traceback(traceback) from exc_value
  File "/usr/local/lib/python3.10/site-packages/django/db/backends/utils.py", line 89, in _execute
    return self.cursor.execute(sql, params)
  File "/usr/local/lib/python3.10/site-packages/django/db/backends/sqlite3/base.py", line 477, in execute
    return Database.Cursor.execute(self, query, params)
django.db.utils.OperationalError: attempt to write a readonly database
{address space usage: 1344442368 bytes/1282MB} {rss usage: 263335936 bytes/251MB} [pid: 41|app: 0|req: 5/10] 27.52.73.198 () {52 vars in 1162 bytes} [Mon May 16 16:16:57 2022] POST /accounts/github/login/ => generated 148169 bytes in 2377 msecs (HTTP/1.1 500) 4 headers in 167 bytes (1 switches on core 0)
...The work of process 41 is done. Seeya!
worker 1 killed successfully (pid: 41)
Respawned uWSGI worker 1 (new pid: 45)
*** Starting uWSGI 2.0.20 (64bit) on [Mon May 16 08:27:43 2022] ***
compiled with version: 10.2.1 20210110 on 16 May 2022 07:43:52
os: Linux-3.10.0-1160.62.1.el7.x86_64 #1 SMP Tue Apr 5 16:57:59 UTC 2022
nodename: 92d3dd22f80c
machine: x86_64
clock source: unix
pcre jit disabled
detected number of CPU cores: 2
current working directory: /var/www/html/Alzheimer_web
writing pidfile to /tmp/Alzheimer_web-master.pid
detected binary path: /usr/local/bin/uwsgi
chdir() to /var/www/html/Alzheimer_web
your memory page size is 4096 bytes
 *** WARNING: you have enabled harakiri without post buffering. Slow upload could be rejected on post-unbuffered webservers *** 
detected max file descriptor number: 1048576
lock engine: pthread robust mutexes
thunder lock: disabled (you can enable it with --thunder-lock)
uwsgi socket 0 bound to TCP address 0.0.0.0:8000 fd 6
setgid() to 33
setuid() to 33
Python version: 3.10.4 (main, May 11 2022, 07:15:55) [GCC 10.2.1 20210110]
*** Python threads support is disabled. You can enable it with --enable-threads ***
Python main interpreter initialized at 0x55cd6893edd0
your server socket listen backlog is limited to 100 connections
your mercy for graceful operations on workers is 60 seconds
mapped 403077 bytes (393 KB) for 2 cores
*** Operational MODE: preforking ***
WSGI app 0 (mountpoint='') ready in 1 seconds on interpreter 0x55cd6893edd0 pid: 11 (default app)
*** uWSGI is running in multiple interpreter mode ***
spawned uWSGI master process (pid: 11)
spawned uWSGI worker 1 (pid: 13, cores: 1)
spawned uWSGI worker 2 (pid: 14, cores: 1)
2022-05-16 16:28:10.270974: W tensorflow/stream_executor/platform/default/dso_loader.cc:64] Could not load dynamic library 'libcudart.so.11.0'; dlerror: libcudart.so.11.0: cannot open shared object file: No such file or directory
2022-05-16 16:28:10.271101: I tensorflow/stream_executor/cuda/cudart_stub.cc:29] Ignore above cudart dlerror if you do not have a GPU set up on your machine.
{address space usage: 1342337024 bytes/1280MB} {rss usage: 261275648 bytes/249MB} [pid: 13|app: 0|req: 1/1] 27.52.73.198 () {44 vars in 927 bytes} [Mon May 16 16:28:09 2022] GET /login/ => generated 3686 bytes in 2832 msecs (HTTP/1.1 200) 8 headers in 390 bytes (1 switches on core 0)
...The work of process 13 is done. Seeya!
worker 1 killed successfully (pid: 13)
Respawned uWSGI worker 1 (new pid: 16)
2022-05-16 16:28:16.807430: W tensorflow/stream_executor/platform/default/dso_loader.cc:64] Could not load dynamic library 'libcudart.so.11.0'; dlerror: libcudart.so.11.0: cannot open shared object file: No such file or directory
2022-05-16 16:28:16.807533: I tensorflow/stream_executor/cuda/cudart_stub.cc:29] Ignore above cudart dlerror if you do not have a GPU set up on your machine.
{address space usage: 1342337024 bytes/1280MB} {rss usage: 261414912 bytes/249MB} [pid: 14|app: 0|req: 1/2] 27.52.73.198 () {44 vars in 933 bytes} [Mon May 16 16:28:16 2022] GET /register/ => generated 4155 bytes in 2350 msecs (HTTP/1.1 200) 8 headers in 390 bytes (1 switches on core 0)
...The work of process 14 is done. Seeya!
worker 2 killed successfully (pid: 14)
Respawned uWSGI worker 2 (new pid: 18)
2022-05-16 16:28:48.374717: W tensorflow/stream_executor/platform/default/dso_loader.cc:64] Could not load dynamic library 'libcudart.so.11.0'; dlerror: libcudart.so.11.0: cannot open shared object file: No such file or directory
2022-05-16 16:28:48.374817: I tensorflow/stream_executor/cuda/cudart_stub.cc:29] Ignore above cudart dlerror if you do not have a GPU set up on your machine.
Internal Server Error: /register/
Traceback (most recent call last):
  File "/usr/local/lib/python3.10/site-packages/django/db/backends/utils.py", line 89, in _execute
    return self.cursor.execute(sql, params)
  File "/usr/local/lib/python3.10/site-packages/django/db/backends/sqlite3/base.py", line 477, in execute
    return Database.Cursor.execute(self, query, params)
sqlite3.OperationalError: attempt to write a readonly database

The above exception was the direct cause of the following exception:

Traceback (most recent call last):
  File "/usr/local/lib/python3.10/site-packages/django/core/handlers/exception.py", line 55, in inner
    response = get_response(request)
  File "/usr/local/lib/python3.10/site-packages/django/core/handlers/base.py", line 197, in _get_response
    response = wrapped_callback(request, *callback_args, **callback_kwargs)
  File "/var/www/html/Alzheimer_web/./login/views.py", line 15, in sign_up
    form.save()
  File "/usr/local/lib/python3.10/site-packages/django/contrib/auth/forms.py", line 143, in save
    user.save()
  File "/usr/local/lib/python3.10/site-packages/django/contrib/auth/base_user.py", line 68, in save
    super().save(*args, **kwargs)
  File "/usr/local/lib/python3.10/site-packages/django/db/models/base.py", line 806, in save
    self.save_base(
  File "/usr/local/lib/python3.10/site-packages/django/db/models/base.py", line 857, in save_base
    updated = self._save_table(
  File "/usr/local/lib/python3.10/site-packages/django/db/models/base.py", line 1000, in _save_table
    results = self._do_insert(
  File "/usr/local/lib/python3.10/site-packages/django/db/models/base.py", line 1041, in _do_insert
    return manager._insert(
  File "/usr/local/lib/python3.10/site-packages/django/db/models/manager.py", line 85, in manager_method
    return getattr(self.get_queryset(), name)(*args, **kwargs)
  File "/usr/local/lib/python3.10/site-packages/django/db/models/query.py", line 1434, in _insert
    return query.get_compiler(using=using).execute_sql(returning_fields)
  File "/usr/local/lib/python3.10/site-packages/django/db/models/sql/compiler.py", line 1621, in execute_sql
    cursor.execute(sql, params)
  File "/usr/local/lib/python3.10/site-packages/django/db/backends/utils.py", line 103, in execute
    return super().execute(sql, params)
  File "/usr/local/lib/python3.10/site-packages/django/db/backends/utils.py", line 67, in execute
    return self._execute_with_wrappers(
  File "/usr/local/lib/python3.10/site-packages/django/db/backends/utils.py", line 80, in _execute_with_wrappers
    return executor(sql, params, many, context)
  File "/usr/local/lib/python3.10/site-packages/django/db/backends/utils.py", line 84, in _execute
    with self.db.wrap_database_errors:
  File "/usr/local/lib/python3.10/site-packages/django/db/utils.py", line 91, in __exit__
    raise dj_exc_value.with_traceback(traceback) from exc_value
  File "/usr/local/lib/python3.10/site-packages/django/db/backends/utils.py", line 89, in _execute
    return self.cursor.execute(sql, params)
  File "/usr/local/lib/python3.10/site-packages/django/db/backends/sqlite3/base.py", line 477, in execute
    return Database.Cursor.execute(self, query, params)
django.db.utils.OperationalError: attempt to write a readonly database
{address space usage: 1347588096 bytes/1285MB} {rss usage: 266657792 bytes/254MB} [pid: 18|app: 0|req: 2/3] 27.52.73.198 () {52 vars in 1125 bytes} [Mon May 16 16:28:47 2022] POST /register/ => generated 147353 bytes in 2701 msecs (HTTP/1.1 500) 7 headers in 228 bytes (1 switches on core 0)
...The work of process 18 is done. Seeya!
worker 2 killed successfully (pid: 18)
Respawned uWSGI worker 2 (new pid: 20)
2022-05-16 16:39:44.939258: W tensorflow/stream_executor/platform/default/dso_loader.cc:64] Could not load dynamic library 'libcudart.so.11.0'; dlerror: libcudart.so.11.0: cannot open shared object file: No such file or directory
2022-05-16 16:39:44.939398: I tensorflow/stream_executor/cuda/cudart_stub.cc:29] Ignore above cudart dlerror if you do not have a GPU set up on your machine.
Internal Server Error: /register/
Traceback (most recent call last):
  File "/usr/local/lib/python3.10/site-packages/django/db/backends/utils.py", line 89, in _execute
    return self.cursor.execute(sql, params)
  File "/usr/local/lib/python3.10/site-packages/django/db/backends/sqlite3/base.py", line 477, in execute
    return Database.Cursor.execute(self, query, params)
sqlite3.OperationalError: attempt to write a readonly database

The above exception was the direct cause of the following exception:

Traceback (most recent call last):
  File "/usr/local/lib/python3.10/site-packages/django/core/handlers/exception.py", line 55, in inner
    response = get_response(request)
  File "/usr/local/lib/python3.10/site-packages/django/core/handlers/base.py", line 197, in _get_response
    response = wrapped_callback(request, *callback_args, **callback_kwargs)
  File "/var/www/html/Alzheimer_web/./login/views.py", line 15, in sign_up
    form.save()
  File "/usr/local/lib/python3.10/site-packages/django/contrib/auth/forms.py", line 143, in save
    user.save()
  File "/usr/local/lib/python3.10/site-packages/django/contrib/auth/base_user.py", line 68, in save
    super().save(*args, **kwargs)
  File "/usr/local/lib/python3.10/site-packages/django/db/models/base.py", line 806, in save
    self.save_base(
  File "/usr/local/lib/python3.10/site-packages/django/db/models/base.py", line 857, in save_base
    updated = self._save_table(
  File "/usr/local/lib/python3.10/site-packages/django/db/models/base.py", line 1000, in _save_table
    results = self._do_insert(
  File "/usr/local/lib/python3.10/site-packages/django/db/models/base.py", line 1041, in _do_insert
    return manager._insert(
  File "/usr/local/lib/python3.10/site-packages/django/db/models/manager.py", line 85, in manager_method
    return getattr(self.get_queryset(), name)(*args, **kwargs)
  File "/usr/local/lib/python3.10/site-packages/django/db/models/query.py", line 1434, in _insert
    return query.get_compiler(using=using).execute_sql(returning_fields)
  File "/usr/local/lib/python3.10/site-packages/django/db/models/sql/compiler.py", line 1621, in execute_sql
    cursor.execute(sql, params)
  File "/usr/local/lib/python3.10/site-packages/django/db/backends/utils.py", line 103, in execute
    return super().execute(sql, params)
  File "/usr/local/lib/python3.10/site-packages/django/db/backends/utils.py", line 67, in execute
    return self._execute_with_wrappers(
  File "/usr/local/lib/python3.10/site-packages/django/db/backends/utils.py", line 80, in _execute_with_wrappers
    return executor(sql, params, many, context)
  File "/usr/local/lib/python3.10/site-packages/django/db/backends/utils.py", line 84, in _execute
    with self.db.wrap_database_errors:
  File "/usr/local/lib/python3.10/site-packages/django/db/utils.py", line 91, in __exit__
    raise dj_exc_value.with_traceback(traceback) from exc_value
  File "/usr/local/lib/python3.10/site-packages/django/db/backends/utils.py", line 89, in _execute
    return self.cursor.execute(sql, params)
  File "/usr/local/lib/python3.10/site-packages/django/db/backends/sqlite3/base.py", line 477, in execute
    return Database.Cursor.execute(self, query, params)
django.db.utils.OperationalError: attempt to write a readonly database
{address space usage: 1347588096 bytes/1285MB} {rss usage: 266657792 bytes/254MB} [pid: 16|app: 0|req: 2/4] 27.52.73.198 () {52 vars in 1125 bytes} [Mon May 16 16:39:44 2022] POST /register/ => generated 147353 bytes in 2692 msecs (HTTP/1.1 500) 7 headers in 228 bytes (1 switches on core 0)
...The work of process 16 is done. Seeya!
worker 1 killed successfully (pid: 16)
Respawned uWSGI worker 1 (new pid: 37)
*** Starting uWSGI 2.0.20 (64bit) on [Mon May 16 08:40:37 2022] ***
compiled with version: 10.2.1 20210110 on 16 May 2022 07:43:52
os: Linux-3.10.0-1160.62.1.el7.x86_64 #1 SMP Tue Apr 5 16:57:59 UTC 2022
nodename: 92d3dd22f80c
machine: x86_64
clock source: unix
pcre jit disabled
detected number of CPU cores: 2
current working directory: /var/www/html/Alzheimer_web
writing pidfile to /tmp/Alzheimer_web-master.pid
detected binary path: /usr/local/bin/uwsgi
chdir() to /var/www/html/Alzheimer_web
your memory page size is 4096 bytes
 *** WARNING: you have enabled harakiri without post buffering. Slow upload could be rejected on post-unbuffered webservers *** 
detected max file descriptor number: 1048576
lock engine: pthread robust mutexes
thunder lock: disabled (you can enable it with --thunder-lock)
uwsgi socket 0 bound to TCP address 0.0.0.0:8000 fd 6
setgid() to 33
setuid() to 33
Python version: 3.10.4 (main, May 11 2022, 07:15:55) [GCC 10.2.1 20210110]
*** Python threads support is disabled. You can enable it with --enable-threads ***
Python main interpreter initialized at 0x5555c6ceadd0
your server socket listen backlog is limited to 100 connections
your mercy for graceful operations on workers is 60 seconds
mapped 403077 bytes (393 KB) for 2 cores
*** Operational MODE: preforking ***
WSGI app 0 (mountpoint='') ready in 1 seconds on interpreter 0x5555c6ceadd0 pid: 11 (default app)
*** uWSGI is running in multiple interpreter mode ***
spawned uWSGI master process (pid: 11)
spawned uWSGI worker 1 (pid: 13, cores: 1)
spawned uWSGI worker 2 (pid: 14, cores: 1)
2022-05-16 16:42:31.150584: W tensorflow/stream_executor/platform/default/dso_loader.cc:64] Could not load dynamic library 'libcudart.so.11.0'; dlerror: libcudart.so.11.0: cannot open shared object file: No such file or directory
2022-05-16 16:42:31.150694: I tensorflow/stream_executor/cuda/cudart_stub.cc:29] Ignore above cudart dlerror if you do not have a GPU set up on your machine.
Internal Server Error: /register/
Traceback (most recent call last):
  File "/usr/local/lib/python3.10/site-packages/django/db/backends/utils.py", line 89, in _execute
    return self.cursor.execute(sql, params)
  File "/usr/local/lib/python3.10/site-packages/django/db/backends/sqlite3/base.py", line 477, in execute
    return Database.Cursor.execute(self, query, params)
sqlite3.OperationalError: attempt to write a readonly database

The above exception was the direct cause of the following exception:

Traceback (most recent call last):
  File "/usr/local/lib/python3.10/site-packages/django/core/handlers/exception.py", line 55, in inner
    response = get_response(request)
  File "/usr/local/lib/python3.10/site-packages/django/core/handlers/base.py", line 197, in _get_response
    response = wrapped_callback(request, *callback_args, **callback_kwargs)
  File "/var/www/html/Alzheimer_web/./login/views.py", line 15, in sign_up
    form.save()
  File "/usr/local/lib/python3.10/site-packages/django/contrib/auth/forms.py", line 143, in save
    user.save()
  File "/usr/local/lib/python3.10/site-packages/django/contrib/auth/base_user.py", line 68, in save
    super().save(*args, **kwargs)
  File "/usr/local/lib/python3.10/site-packages/django/db/models/base.py", line 806, in save
    self.save_base(
  File "/usr/local/lib/python3.10/site-packages/django/db/models/base.py", line 857, in save_base
    updated = self._save_table(
  File "/usr/local/lib/python3.10/site-packages/django/db/models/base.py", line 1000, in _save_table
    results = self._do_insert(
  File "/usr/local/lib/python3.10/site-packages/django/db/models/base.py", line 1041, in _do_insert
    return manager._insert(
  File "/usr/local/lib/python3.10/site-packages/django/db/models/manager.py", line 85, in manager_method
    return getattr(self.get_queryset(), name)(*args, **kwargs)
  File "/usr/local/lib/python3.10/site-packages/django/db/models/query.py", line 1434, in _insert
    return query.get_compiler(using=using).execute_sql(returning_fields)
  File "/usr/local/lib/python3.10/site-packages/django/db/models/sql/compiler.py", line 1621, in execute_sql
    cursor.execute(sql, params)
  File "/usr/local/lib/python3.10/site-packages/django/db/backends/utils.py", line 103, in execute
    return super().execute(sql, params)
  File "/usr/local/lib/python3.10/site-packages/django/db/backends/utils.py", line 67, in execute
    return self._execute_with_wrappers(
  File "/usr/local/lib/python3.10/site-packages/django/db/backends/utils.py", line 80, in _execute_with_wrappers
    return executor(sql, params, many, context)
  File "/usr/local/lib/python3.10/site-packages/django/db/backends/utils.py", line 84, in _execute
    with self.db.wrap_database_errors:
  File "/usr/local/lib/python3.10/site-packages/django/db/utils.py", line 91, in __exit__
    raise dj_exc_value.with_traceback(traceback) from exc_value
  File "/usr/local/lib/python3.10/site-packages/django/db/backends/utils.py", line 89, in _execute
    return self.cursor.execute(sql, params)
  File "/usr/local/lib/python3.10/site-packages/django/db/backends/sqlite3/base.py", line 477, in execute
    return Database.Cursor.execute(self, query, params)
django.db.utils.OperationalError: attempt to write a readonly database
{address space usage: 1347588096 bytes/1285MB} {rss usage: 266575872 bytes/254MB} [pid: 13|app: 0|req: 1/1] 27.52.73.198 () {52 vars in 1125 bytes} [Mon May 16 16:42:30 2022] POST /register/ => generated 147353 bytes in 2658 msecs (HTTP/1.1 500) 7 headers in 228 bytes (1 switches on core 0)
...The work of process 13 is done. Seeya!
worker 1 killed successfully (pid: 13)
Respawned uWSGI worker 1 (new pid: 16)
2022-05-16 16:43:02.087262: W tensorflow/stream_executor/platform/default/dso_loader.cc:64] Could not load dynamic library 'libcudart.so.11.0'; dlerror: libcudart.so.11.0: cannot open shared object file: No such file or directory
2022-05-16 16:43:02.087418: I tensorflow/stream_executor/cuda/cudart_stub.cc:29] Ignore above cudart dlerror if you do not have a GPU set up on your machine.
{address space usage: 1346539520 bytes/1284MB} {rss usage: 265646080 bytes/253MB} [pid: 14|app: 0|req: 1/2] 27.52.73.198 () {52 vars in 1125 bytes} [Mon May 16 16:43:01 2022] POST /register/ => generated 4389 bytes in 2466 msecs (HTTP/1.1 200) 8 headers in 390 bytes (1 switches on core 0)
...The work of process 14 is done. Seeya!
worker 2 killed successfully (pid: 14)
Respawned uWSGI worker 2 (new pid: 18)
2022-05-16 16:43:22.946255: W tensorflow/stream_executor/platform/default/dso_loader.cc:64] Could not load dynamic library 'libcudart.so.11.0'; dlerror: libcudart.so.11.0: cannot open shared object file: No such file or directory
2022-05-16 16:43:22.946381: I tensorflow/stream_executor/cuda/cudart_stub.cc:29] Ignore above cudart dlerror if you do not have a GPU set up on your machine.
Internal Server Error: /register/
Traceback (most recent call last):
  File "/usr/local/lib/python3.10/site-packages/django/db/backends/utils.py", line 89, in _execute
    return self.cursor.execute(sql, params)
  File "/usr/local/lib/python3.10/site-packages/django/db/backends/sqlite3/base.py", line 477, in execute
    return Database.Cursor.execute(self, query, params)
sqlite3.OperationalError: attempt to write a readonly database

The above exception was the direct cause of the following exception:

Traceback (most recent call last):
  File "/usr/local/lib/python3.10/site-packages/django/core/handlers/exception.py", line 55, in inner
    response = get_response(request)
  File "/usr/local/lib/python3.10/site-packages/django/core/handlers/base.py", line 197, in _get_response
    response = wrapped_callback(request, *callback_args, **callback_kwargs)
  File "/var/www/html/Alzheimer_web/./login/views.py", line 15, in sign_up
    form.save()
  File "/usr/local/lib/python3.10/site-packages/django/contrib/auth/forms.py", line 143, in save
    user.save()
  File "/usr/local/lib/python3.10/site-packages/django/contrib/auth/base_user.py", line 68, in save
    super().save(*args, **kwargs)
  File "/usr/local/lib/python3.10/site-packages/django/db/models/base.py", line 806, in save
    self.save_base(
  File "/usr/local/lib/python3.10/site-packages/django/db/models/base.py", line 857, in save_base
    updated = self._save_table(
  File "/usr/local/lib/python3.10/site-packages/django/db/models/base.py", line 1000, in _save_table
    results = self._do_insert(
  File "/usr/local/lib/python3.10/site-packages/django/db/models/base.py", line 1041, in _do_insert
    return manager._insert(
  File "/usr/local/lib/python3.10/site-packages/django/db/models/manager.py", line 85, in manager_method
    return getattr(self.get_queryset(), name)(*args, **kwargs)
  File "/usr/local/lib/python3.10/site-packages/django/db/models/query.py", line 1434, in _insert
    return query.get_compiler(using=using).execute_sql(returning_fields)
  File "/usr/local/lib/python3.10/site-packages/django/db/models/sql/compiler.py", line 1621, in execute_sql
    cursor.execute(sql, params)
  File "/usr/local/lib/python3.10/site-packages/django/db/backends/utils.py", line 103, in execute
    return super().execute(sql, params)
  File "/usr/local/lib/python3.10/site-packages/django/db/backends/utils.py", line 67, in execute
    return self._execute_with_wrappers(
  File "/usr/local/lib/python3.10/site-packages/django/db/backends/utils.py", line 80, in _execute_with_wrappers
    return executor(sql, params, many, context)
  File "/usr/local/lib/python3.10/site-packages/django/db/backends/utils.py", line 84, in _execute
    with self.db.wrap_database_errors:
  File "/usr/local/lib/python3.10/site-packages/django/db/utils.py", line 91, in __exit__
    raise dj_exc_value.with_traceback(traceback) from exc_value
  File "/usr/local/lib/python3.10/site-packages/django/db/backends/utils.py", line 89, in _execute
    return self.cursor.execute(sql, params)
  File "/usr/local/lib/python3.10/site-packages/django/db/backends/sqlite3/base.py", line 477, in execute
    return Database.Cursor.execute(self, query, params)
django.db.utils.OperationalError: attempt to write a readonly database
{address space usage: 1347592192 bytes/1285MB} {rss usage: 266547200 bytes/254MB} [pid: 18|app: 0|req: 2/3] 27.52.73.198 () {52 vars in 1125 bytes} [Mon May 16 16:43:22 2022] POST /register/ => generated 147353 bytes in 2648 msecs (HTTP/1.1 500) 7 headers in 228 bytes (1 switches on core 0)
...The work of process 18 is done. Seeya!
worker 2 killed successfully (pid: 18)
Respawned uWSGI worker 2 (new pid: 20)
2022-05-16 16:47:36.726159: W tensorflow/stream_executor/platform/default/dso_loader.cc:64] Could not load dynamic library 'libcudart.so.11.0'; dlerror: libcudart.so.11.0: cannot open shared object file: No such file or directory
2022-05-16 16:47:36.726283: I tensorflow/stream_executor/cuda/cudart_stub.cc:29] Ignore above cudart dlerror if you do not have a GPU set up on your machine.
mark456tung@gmail.com
{address space usage: 1347469312 bytes/1285MB} {rss usage: 268345344 bytes/255MB} [pid: 16|app: 0|req: 2/4] 27.52.73.198 () {52 vars in 1125 bytes} [Mon May 16 16:47:36 2022] POST /register/ => generated 0 bytes in 5472 msecs (HTTP/1.1 302) 8 headers in 240 bytes (1 switches on core 0)
...The work of process 16 is done. Seeya!
2022-05-16 16:47:42.439710: W tensorflow/stream_executor/platform/default/dso_loader.cc:64] Could not load dynamic library 'libcudart.so.11.0'; dlerror: libcudart.so.11.0: cannot open shared object file: No such file or directory
2022-05-16 16:47:42.439806: I tensorflow/stream_executor/cuda/cudart_stub.cc:29] Ignore above cudart dlerror if you do not have a GPU set up on your machine.
worker 1 killed successfully (pid: 16)
Respawned uWSGI worker 1 (new pid: 22)
{address space usage: 1341280256 bytes/1279MB} {rss usage: 260403200 bytes/248MB} [pid: 20|app: 0|req: 3/5] 27.52.73.198 () {46 vars in 959 bytes} [Mon May 16 16:47:41 2022] GET /login => generated 0 bytes in 2543 msecs (HTTP/1.1 301) 6 headers in 216 bytes (1 switches on core 0)
...The work of process 20 is done. Seeya!
2022-05-16 16:47:45.144612: W tensorflow/stream_executor/platform/default/dso_loader.cc:64] Could not load dynamic library 'libcudart.so.11.0'; dlerror: libcudart.so.11.0: cannot open shared object file: No such file or directory
2022-05-16 16:47:45.144710: I tensorflow/stream_executor/cuda/cudart_stub.cc:29] Ignore above cudart dlerror if you do not have a GPU set up on your machine.
worker 2 killed successfully (pid: 20)
Respawned uWSGI worker 2 (new pid: 24)
{address space usage: 1342345216 bytes/1280MB} {rss usage: 261160960 bytes/249MB} [pid: 22|app: 0|req: 3/6] 27.52.73.198 () {46 vars in 961 bytes} [Mon May 16 16:47:44 2022] GET /login/ => generated 3686 bytes in 2539 msecs (HTTP/1.1 200) 8 headers in 390 bytes (1 switches on core 0)
{address space usage: 1343393792 bytes/1281MB} {rss usage: 262529024 bytes/250MB} [pid: 22|app: 0|req: 4/7] 27.52.73.198 () {52 vars in 1116 bytes} [Mon May 16 16:47:58 2022] POST /login/ => generated 0 bytes in 267 msecs (HTTP/1.1 302) 10 headers in 548 bytes (1 switches on core 0)
...The work of process 22 is done. Seeya!
2022-05-16 16:47:59.023022: W tensorflow/stream_executor/platform/default/dso_loader.cc:64] Could not load dynamic library 'libcudart.so.11.0'; dlerror: libcudart.so.11.0: cannot open shared object file: No such file or directory
2022-05-16 16:47:59.023117: I tensorflow/stream_executor/cuda/cudart_stub.cc:29] Ignore above cudart dlerror if you do not have a GPU set up on your machine.
worker 1 killed successfully (pid: 22)
Respawned uWSGI worker 1 (new pid: 26)
{address space usage: 1342345216 bytes/1280MB} {rss usage: 262213632 bytes/250MB} [pid: 24|app: 0|req: 4/8] 27.52.73.198 () {46 vars in 990 bytes} [Mon May 16 16:47:58 2022] GET / => generated 16768 bytes in 2513 msecs (HTTP/1.1 200) 7 headers in 223 bytes (1 switches on core 0)
...The work of process 24 is done. Seeya!
worker 2 killed successfully (pid: 24)
Respawned uWSGI worker 2 (new pid: 28)
2022-05-16 16:48:15.729622: W tensorflow/stream_executor/platform/default/dso_loader.cc:64] Could not load dynamic library 'libcudart.so.11.0'; dlerror: libcudart.so.11.0: cannot open shared object file: No such file or directory
2022-05-16 16:48:15.729721: I tensorflow/stream_executor/cuda/cudart_stub.cc:29] Ignore above cudart dlerror if you do not have a GPU set up on your machine.
{address space usage: 1343393792 bytes/1281MB} {rss usage: 262381568 bytes/250MB} [pid: 28|app: 0|req: 5/9] 27.52.73.198 () {44 vars in 967 bytes} [Mon May 16 16:48:15 2022] GET /upload/ => generated 3505 bytes in 2373 msecs (HTTP/1.1 200) 8 headers in 390 bytes (1 switches on core 0)
...The work of process 28 is done. Seeya!
2022-05-16 16:48:18.482329: W tensorflow/stream_executor/platform/default/dso_loader.cc:64] Could not load dynamic library 'libcudart.so.11.0'; dlerror: libcudart.so.11.0: cannot open shared object file: No such file or directory
2022-05-16 16:48:18.482431: I tensorflow/stream_executor/cuda/cudart_stub.cc:29] Ignore above cudart dlerror if you do not have a GPU set up on your machine.
worker 2 killed successfully (pid: 28)
Respawned uWSGI worker 2 (new pid: 30)
{address space usage: 1343393792 bytes/1281MB} {rss usage: 262381568 bytes/250MB} [pid: 26|app: 0|req: 5/10] 27.52.73.198 () {42 vars in 868 bytes} [Mon May 16 16:48:17 2022] GET /upload/ => generated 3505 bytes in 2454 msecs (HTTP/1.1 200) 8 headers in 390 bytes (1 switches on core 0)
...The work of process 26 is done. Seeya!
worker 1 killed successfully (pid: 26)
Respawned uWSGI worker 1 (new pid: 32)
2022-05-16 16:48:42.640982: W tensorflow/stream_executor/platform/default/dso_loader.cc:64] Could not load dynamic library 'libcudart.so.11.0'; dlerror: libcudart.so.11.0: cannot open shared object file: No such file or directory
2022-05-16 16:48:42.641074: I tensorflow/stream_executor/cuda/cudart_stub.cc:29] Ignore above cudart dlerror if you do not have a GPU set up on your machine.
{address space usage: 1344700416 bytes/1282MB} {rss usage: 264138752 bytes/251MB} [pid: 30|app: 0|req: 6/11] 27.52.73.198 () {52 vars in 1235 bytes} [Mon May 16 16:48:42 2022] POST /upload/ => generated 0 bytes in 2451 msecs (HTTP/1.1 302) 8 headers in 243 bytes (1 switches on core 0)
...The work of process 30 is done. Seeya!
2022-05-16 16:48:45.429618: W tensorflow/stream_executor/platform/default/dso_loader.cc:64] Could not load dynamic library 'libcudart.so.11.0'; dlerror: libcudart.so.11.0: cannot open shared object file: No such file or directory
2022-05-16 16:48:45.429712: I tensorflow/stream_executor/cuda/cudart_stub.cc:29] Ignore above cudart dlerror if you do not have a GPU set up on your machine.
worker 2 killed successfully (pid: 30)
Respawned uWSGI worker 2 (new pid: 34)
2022-05-16 16:48:47.886688: W tensorflow/stream_executor/platform/default/dso_loader.cc:64] Could not load dynamic library 'libcuda.so.1'; dlerror: libcuda.so.1: cannot open shared object file: No such file or directory
2022-05-16 16:48:47.930527: W tensorflow/stream_executor/cuda/cuda_driver.cc:269] failed call to cuInit: UNKNOWN ERROR (303)
2022-05-16 16:48:47.930665: I tensorflow/stream_executor/cuda/cuda_diagnostics.cc:156] kernel driver does not appear to be running on this host (92d3dd22f80c): /proc/driver/nvidia/version does not exist
2022-05-16 16:48:47.985238: I tensorflow/core/platform/cpu_feature_guard.cc:151] This TensorFlow binary is optimized with oneAPI Deep Neural Network Library (oneDNN) to use the following CPU instructions in performance-critical operations:  AVX2 FMA
To enable them in other operations, rebuild TensorFlow with the appropriate compiler flags.
2022-05-16 16:48:53.317512: W tensorflow/core/framework/cpu_allocator_impl.cc:82] Allocation of 822083584 exceeds 10% of free system memory.
2022-05-16 16:48:55.424327: W tensorflow/core/framework/cpu_allocator_impl.cc:82] Allocation of 822083584 exceeds 10% of free system memory.
2022-05-16 16:48:56.490770: W tensorflow/core/framework/cpu_allocator_impl.cc:82] Allocation of 822083584 exceeds 10% of free system memory.
DAMN ! worker 1 (pid: 32) died, killed by signal 9 :( trying respawn ...
Respawned uWSGI worker 1 (new pid: 41)
2022-05-16 16:50:57.566983: W tensorflow/stream_executor/platform/default/dso_loader.cc:64] Could not load dynamic library 'libcudart.so.11.0'; dlerror: libcudart.so.11.0: cannot open shared object file: No such file or directory
2022-05-16 16:50:57.567120: I tensorflow/stream_executor/cuda/cudart_stub.cc:29] Ignore above cudart dlerror if you do not have a GPU set up on your machine.
{address space usage: 1342337024 bytes/1280MB} {rss usage: 260943872 bytes/248MB} [pid: 41|app: 0|req: 7/12] 3.8.95.141 () {36 vars in 541 bytes} [Mon May 16 16:50:55 2022] HEAD / => generated 16548 bytes in 6694 msecs (HTTP/1.1 200) 7 headers in 223 bytes (1 switches on core 0)
...The work of process 41 is done. Seeya!
worker 1 killed successfully (pid: 41)
Respawned uWSGI worker 1 (new pid: 53)
